{
 "cells": [
  {
   "cell_type": "code",
   "execution_count": 7,
   "id": "df480f8d-f2b0-42c2-ad45-20fe9586666d",
   "metadata": {},
   "outputs": [
    {
     "name": "stdout",
     "output_type": "stream",
     "text": [
      "\n",
      "  You can now view your Streamlit app in your browser.\n",
      "\n",
      "  Local URL: http://localhost:8501\n",
      "  Network URL: http://192.168.1.20:8501\n",
      "\n",
      "df shape = (61502, 540)\n",
      " * Serving Flask app 'API_01_G10'\n",
      " * Debug mode: on\n"
     ]
    },
    {
     "name": "stderr",
     "output_type": "stream",
     "text": [
      "\u001b[31m\u001b[1mWARNING: This is a development server. Do not use it in a production deployment. Use a production WSGI server instead.\u001b[0m\n",
      " * Running on http://127.0.0.1:5000\n",
      "\u001b[33mPress CTRL+C to quit\u001b[0m\n",
      " * Restarting with watchdog (inotify)\n",
      " * Debugger is active!\n",
      " * Debugger PIN: 506-688-256\n",
      "2025-09-15 15:12:58.844 Serialization of dataframe to Arrow table was unsuccessful. Applying automatic fixes for column types to make the dataframe Arrow-compatible.\n",
      "Traceback (most recent call last):\n",
      "  File \"/home/riad/anaconda3/envs/VERT211/lib/python3.10/site-packages/streamlit/dataframe_util.py\", line 822, in convert_pandas_df_to_arrow_bytes\n",
      "    table = pa.Table.from_pandas(df)\n",
      "  File \"pyarrow/table.pxi\", line 3475, in pyarrow.lib.Table.from_pandas\n",
      "  File \"/home/riad/anaconda3/envs/VERT211/lib/python3.10/site-packages/pyarrow/pandas_compat.py\", line 611, in dataframe_to_arrays\n",
      "    arrays = [convert_column(c, f)\n",
      "  File \"/home/riad/anaconda3/envs/VERT211/lib/python3.10/site-packages/pyarrow/pandas_compat.py\", line 611, in <listcomp>\n",
      "    arrays = [convert_column(c, f)\n",
      "  File \"/home/riad/anaconda3/envs/VERT211/lib/python3.10/site-packages/pyarrow/pandas_compat.py\", line 598, in convert_column\n",
      "    raise e\n",
      "  File \"/home/riad/anaconda3/envs/VERT211/lib/python3.10/site-packages/pyarrow/pandas_compat.py\", line 592, in convert_column\n",
      "    result = pa.array(col, type=type_, from_pandas=True, safe=safe)\n",
      "  File \"pyarrow/array.pxi\", line 316, in pyarrow.lib.array\n",
      "  File \"pyarrow/array.pxi\", line 83, in pyarrow.lib._ndarray_to_array\n",
      "  File \"pyarrow/error.pxi\", line 123, in pyarrow.lib.check_status\n",
      "pyarrow.lib.ArrowTypeError: (\"Expected bytes, got a 'int' object\", 'Conversion failed for column 232927 with type object')\n",
      "127.0.0.1 - - [15/Sep/2025 15:13:01] \"GET /credit/369780 HTTP/1.1\" 200 -\n",
      "127.0.0.1 - - [15/Sep/2025 15:13:03] \"GET /credit/369780 HTTP/1.1\" 200 -\n",
      "2025-09-15 15:13:16.516 Serialization of dataframe to Arrow table was unsuccessful. Applying automatic fixes for column types to make the dataframe Arrow-compatible.\n",
      "Traceback (most recent call last):\n",
      "  File \"/home/riad/anaconda3/envs/VERT211/lib/python3.10/site-packages/streamlit/dataframe_util.py\", line 822, in convert_pandas_df_to_arrow_bytes\n",
      "    table = pa.Table.from_pandas(df)\n",
      "  File \"pyarrow/table.pxi\", line 3475, in pyarrow.lib.Table.from_pandas\n",
      "  File \"/home/riad/anaconda3/envs/VERT211/lib/python3.10/site-packages/pyarrow/pandas_compat.py\", line 611, in dataframe_to_arrays\n",
      "    arrays = [convert_column(c, f)\n",
      "  File \"/home/riad/anaconda3/envs/VERT211/lib/python3.10/site-packages/pyarrow/pandas_compat.py\", line 611, in <listcomp>\n",
      "    arrays = [convert_column(c, f)\n",
      "  File \"/home/riad/anaconda3/envs/VERT211/lib/python3.10/site-packages/pyarrow/pandas_compat.py\", line 598, in convert_column\n",
      "    raise e\n",
      "  File \"/home/riad/anaconda3/envs/VERT211/lib/python3.10/site-packages/pyarrow/pandas_compat.py\", line 592, in convert_column\n",
      "    result = pa.array(col, type=type_, from_pandas=True, safe=safe)\n",
      "  File \"pyarrow/array.pxi\", line 316, in pyarrow.lib.array\n",
      "  File \"pyarrow/array.pxi\", line 83, in pyarrow.lib._ndarray_to_array\n",
      "  File \"pyarrow/error.pxi\", line 123, in pyarrow.lib.check_status\n",
      "pyarrow.lib.ArrowTypeError: (\"Expected bytes, got a 'int' object\", 'Conversion failed for column 232927 with type object')\n",
      "127.0.0.1 - - [15/Sep/2025 15:13:16] \"GET /credit/369780 HTTP/1.1\" 200 -\n",
      "127.0.0.1 - - [15/Sep/2025 15:13:18] \"GET /credit/369780 HTTP/1.1\" 200 -\n",
      "2025-09-15 15:13:43.319 Serialization of dataframe to Arrow table was unsuccessful. Applying automatic fixes for column types to make the dataframe Arrow-compatible.\n",
      "Traceback (most recent call last):\n",
      "  File \"/home/riad/anaconda3/envs/VERT211/lib/python3.10/site-packages/streamlit/dataframe_util.py\", line 822, in convert_pandas_df_to_arrow_bytes\n",
      "    table = pa.Table.from_pandas(df)\n",
      "  File \"pyarrow/table.pxi\", line 3475, in pyarrow.lib.Table.from_pandas\n",
      "  File \"/home/riad/anaconda3/envs/VERT211/lib/python3.10/site-packages/pyarrow/pandas_compat.py\", line 611, in dataframe_to_arrays\n",
      "    arrays = [convert_column(c, f)\n",
      "  File \"/home/riad/anaconda3/envs/VERT211/lib/python3.10/site-packages/pyarrow/pandas_compat.py\", line 611, in <listcomp>\n",
      "    arrays = [convert_column(c, f)\n",
      "  File \"/home/riad/anaconda3/envs/VERT211/lib/python3.10/site-packages/pyarrow/pandas_compat.py\", line 598, in convert_column\n",
      "    raise e\n",
      "  File \"/home/riad/anaconda3/envs/VERT211/lib/python3.10/site-packages/pyarrow/pandas_compat.py\", line 592, in convert_column\n",
      "    result = pa.array(col, type=type_, from_pandas=True, safe=safe)\n",
      "  File \"pyarrow/array.pxi\", line 316, in pyarrow.lib.array\n",
      "  File \"pyarrow/array.pxi\", line 83, in pyarrow.lib._ndarray_to_array\n",
      "  File \"pyarrow/error.pxi\", line 123, in pyarrow.lib.check_status\n",
      "pyarrow.lib.ArrowTypeError: (\"Expected bytes, got a 'int' object\", 'Conversion failed for column 232927 with type object')\n",
      "127.0.0.1 - - [15/Sep/2025 15:13:43] \"GET /credit/369780 HTTP/1.1\" 200 -\n",
      "127.0.0.1 - - [15/Sep/2025 15:13:44] \"GET /credit/369780 HTTP/1.1\" 200 -\n",
      "2025-09-15 15:13:56.264 Serialization of dataframe to Arrow table was unsuccessful. Applying automatic fixes for column types to make the dataframe Arrow-compatible.\n",
      "Traceback (most recent call last):\n",
      "  File \"/home/riad/anaconda3/envs/VERT211/lib/python3.10/site-packages/streamlit/dataframe_util.py\", line 822, in convert_pandas_df_to_arrow_bytes\n",
      "    table = pa.Table.from_pandas(df)\n",
      "  File \"pyarrow/table.pxi\", line 3475, in pyarrow.lib.Table.from_pandas\n",
      "  File \"/home/riad/anaconda3/envs/VERT211/lib/python3.10/site-packages/pyarrow/pandas_compat.py\", line 611, in dataframe_to_arrays\n",
      "    arrays = [convert_column(c, f)\n",
      "  File \"/home/riad/anaconda3/envs/VERT211/lib/python3.10/site-packages/pyarrow/pandas_compat.py\", line 611, in <listcomp>\n",
      "    arrays = [convert_column(c, f)\n",
      "  File \"/home/riad/anaconda3/envs/VERT211/lib/python3.10/site-packages/pyarrow/pandas_compat.py\", line 598, in convert_column\n",
      "    raise e\n",
      "  File \"/home/riad/anaconda3/envs/VERT211/lib/python3.10/site-packages/pyarrow/pandas_compat.py\", line 592, in convert_column\n",
      "    result = pa.array(col, type=type_, from_pandas=True, safe=safe)\n",
      "  File \"pyarrow/array.pxi\", line 316, in pyarrow.lib.array\n",
      "  File \"pyarrow/array.pxi\", line 83, in pyarrow.lib._ndarray_to_array\n",
      "  File \"pyarrow/error.pxi\", line 123, in pyarrow.lib.check_status\n",
      "pyarrow.lib.ArrowTypeError: (\"Expected bytes, got a 'int' object\", 'Conversion failed for column 232927 with type object')\n",
      "127.0.0.1 - - [15/Sep/2025 15:13:56] \"GET /credit/369780 HTTP/1.1\" 200 -\n",
      "127.0.0.1 - - [15/Sep/2025 15:13:57] \"GET /credit/369780 HTTP/1.1\" 200 -\n",
      "2025-09-15 15:14:09.991 Serialization of dataframe to Arrow table was unsuccessful. Applying automatic fixes for column types to make the dataframe Arrow-compatible.\n",
      "Traceback (most recent call last):\n",
      "  File \"/home/riad/anaconda3/envs/VERT211/lib/python3.10/site-packages/streamlit/dataframe_util.py\", line 822, in convert_pandas_df_to_arrow_bytes\n",
      "    table = pa.Table.from_pandas(df)\n",
      "  File \"pyarrow/table.pxi\", line 3475, in pyarrow.lib.Table.from_pandas\n",
      "  File \"/home/riad/anaconda3/envs/VERT211/lib/python3.10/site-packages/pyarrow/pandas_compat.py\", line 611, in dataframe_to_arrays\n",
      "    arrays = [convert_column(c, f)\n",
      "  File \"/home/riad/anaconda3/envs/VERT211/lib/python3.10/site-packages/pyarrow/pandas_compat.py\", line 611, in <listcomp>\n",
      "    arrays = [convert_column(c, f)\n",
      "  File \"/home/riad/anaconda3/envs/VERT211/lib/python3.10/site-packages/pyarrow/pandas_compat.py\", line 598, in convert_column\n",
      "    raise e\n",
      "  File \"/home/riad/anaconda3/envs/VERT211/lib/python3.10/site-packages/pyarrow/pandas_compat.py\", line 592, in convert_column\n",
      "    result = pa.array(col, type=type_, from_pandas=True, safe=safe)\n",
      "  File \"pyarrow/array.pxi\", line 316, in pyarrow.lib.array\n",
      "  File \"pyarrow/array.pxi\", line 83, in pyarrow.lib._ndarray_to_array\n",
      "  File \"pyarrow/error.pxi\", line 123, in pyarrow.lib.check_status\n",
      "pyarrow.lib.ArrowTypeError: (\"Expected bytes, got a 'int' object\", 'Conversion failed for column 232927 with type object')\n",
      "127.0.0.1 - - [15/Sep/2025 15:14:10] \"GET /credit/369780 HTTP/1.1\" 200 -\n",
      "127.0.0.1 - - [15/Sep/2025 15:14:11] \"GET /credit/369780 HTTP/1.1\" 200 -\n",
      "2025-09-15 15:14:42.266 Serialization of dataframe to Arrow table was unsuccessful. Applying automatic fixes for column types to make the dataframe Arrow-compatible.\n",
      "Traceback (most recent call last):\n",
      "  File \"/home/riad/anaconda3/envs/VERT211/lib/python3.10/site-packages/streamlit/dataframe_util.py\", line 822, in convert_pandas_df_to_arrow_bytes\n",
      "    table = pa.Table.from_pandas(df)\n",
      "  File \"pyarrow/table.pxi\", line 3475, in pyarrow.lib.Table.from_pandas\n",
      "  File \"/home/riad/anaconda3/envs/VERT211/lib/python3.10/site-packages/pyarrow/pandas_compat.py\", line 611, in dataframe_to_arrays\n",
      "    arrays = [convert_column(c, f)\n",
      "  File \"/home/riad/anaconda3/envs/VERT211/lib/python3.10/site-packages/pyarrow/pandas_compat.py\", line 611, in <listcomp>\n",
      "    arrays = [convert_column(c, f)\n",
      "  File \"/home/riad/anaconda3/envs/VERT211/lib/python3.10/site-packages/pyarrow/pandas_compat.py\", line 598, in convert_column\n",
      "    raise e\n",
      "  File \"/home/riad/anaconda3/envs/VERT211/lib/python3.10/site-packages/pyarrow/pandas_compat.py\", line 592, in convert_column\n",
      "    result = pa.array(col, type=type_, from_pandas=True, safe=safe)\n",
      "  File \"pyarrow/array.pxi\", line 316, in pyarrow.lib.array\n",
      "  File \"pyarrow/array.pxi\", line 83, in pyarrow.lib._ndarray_to_array\n",
      "  File \"pyarrow/error.pxi\", line 123, in pyarrow.lib.check_status\n",
      "pyarrow.lib.ArrowTypeError: (\"Expected bytes, got a 'int' object\", 'Conversion failed for column 232927 with type object')\n",
      "127.0.0.1 - - [15/Sep/2025 15:14:42] \"GET /credit/369780 HTTP/1.1\" 200 -\n",
      "127.0.0.1 - - [15/Sep/2025 15:14:44] \"GET /credit/369780 HTTP/1.1\" 200 -\n",
      "2025-09-15 15:15:04.379 Serialization of dataframe to Arrow table was unsuccessful. Applying automatic fixes for column types to make the dataframe Arrow-compatible.\n",
      "Traceback (most recent call last):\n",
      "  File \"/home/riad/anaconda3/envs/VERT211/lib/python3.10/site-packages/streamlit/dataframe_util.py\", line 822, in convert_pandas_df_to_arrow_bytes\n",
      "    table = pa.Table.from_pandas(df)\n",
      "  File \"pyarrow/table.pxi\", line 3475, in pyarrow.lib.Table.from_pandas\n",
      "  File \"/home/riad/anaconda3/envs/VERT211/lib/python3.10/site-packages/pyarrow/pandas_compat.py\", line 611, in dataframe_to_arrays\n",
      "    arrays = [convert_column(c, f)\n",
      "  File \"/home/riad/anaconda3/envs/VERT211/lib/python3.10/site-packages/pyarrow/pandas_compat.py\", line 611, in <listcomp>\n",
      "    arrays = [convert_column(c, f)\n",
      "  File \"/home/riad/anaconda3/envs/VERT211/lib/python3.10/site-packages/pyarrow/pandas_compat.py\", line 598, in convert_column\n",
      "    raise e\n",
      "  File \"/home/riad/anaconda3/envs/VERT211/lib/python3.10/site-packages/pyarrow/pandas_compat.py\", line 592, in convert_column\n",
      "    result = pa.array(col, type=type_, from_pandas=True, safe=safe)\n",
      "  File \"pyarrow/array.pxi\", line 316, in pyarrow.lib.array\n",
      "  File \"pyarrow/array.pxi\", line 83, in pyarrow.lib._ndarray_to_array\n",
      "  File \"pyarrow/error.pxi\", line 123, in pyarrow.lib.check_status\n",
      "pyarrow.lib.ArrowTypeError: (\"Expected bytes, got a 'int' object\", 'Conversion failed for column 232927 with type object')\n",
      "127.0.0.1 - - [15/Sep/2025 15:15:04] \"GET /credit/369780 HTTP/1.1\" 200 -\n",
      "127.0.0.1 - - [15/Sep/2025 15:15:05] \"GET /credit/369780 HTTP/1.1\" 200 -\n",
      "2025-09-15 15:15:18.331 Serialization of dataframe to Arrow table was unsuccessful. Applying automatic fixes for column types to make the dataframe Arrow-compatible.\n",
      "Traceback (most recent call last):\n",
      "  File \"/home/riad/anaconda3/envs/VERT211/lib/python3.10/site-packages/streamlit/dataframe_util.py\", line 822, in convert_pandas_df_to_arrow_bytes\n",
      "    table = pa.Table.from_pandas(df)\n",
      "  File \"pyarrow/table.pxi\", line 3475, in pyarrow.lib.Table.from_pandas\n",
      "  File \"/home/riad/anaconda3/envs/VERT211/lib/python3.10/site-packages/pyarrow/pandas_compat.py\", line 611, in dataframe_to_arrays\n",
      "    arrays = [convert_column(c, f)\n",
      "  File \"/home/riad/anaconda3/envs/VERT211/lib/python3.10/site-packages/pyarrow/pandas_compat.py\", line 611, in <listcomp>\n",
      "    arrays = [convert_column(c, f)\n",
      "  File \"/home/riad/anaconda3/envs/VERT211/lib/python3.10/site-packages/pyarrow/pandas_compat.py\", line 598, in convert_column\n",
      "    raise e\n",
      "  File \"/home/riad/anaconda3/envs/VERT211/lib/python3.10/site-packages/pyarrow/pandas_compat.py\", line 592, in convert_column\n",
      "    result = pa.array(col, type=type_, from_pandas=True, safe=safe)\n",
      "  File \"pyarrow/array.pxi\", line 316, in pyarrow.lib.array\n",
      "  File \"pyarrow/array.pxi\", line 83, in pyarrow.lib._ndarray_to_array\n",
      "  File \"pyarrow/error.pxi\", line 123, in pyarrow.lib.check_status\n",
      "pyarrow.lib.ArrowTypeError: (\"Expected bytes, got a 'int' object\", 'Conversion failed for column 232927 with type object')\n",
      "127.0.0.1 - - [15/Sep/2025 15:15:18] \"GET /credit/369780 HTTP/1.1\" 200 -\n",
      "127.0.0.1 - - [15/Sep/2025 15:15:19] \"GET /credit/369780 HTTP/1.1\" 200 -\n"
     ]
    },
    {
     "name": "stdout",
     "output_type": "stream",
     "text": [
      "  Stopping...\n",
      "df shape = (61502, 540)\n",
      "id client =  369780\n",
      "X shape =  (1, 539)\n",
      "id client =  369780\n",
      "X shape =  (1, 539)\n",
      "id client =  369780\n",
      "X shape =  (1, 539)\n",
      "id client =  369780\n",
      "X shape =  (1, 539)\n",
      "id client =  369780\n",
      "X shape =  (1, 539)\n",
      "id client =  369780\n",
      "X shape =  (1, 539)\n",
      "id client =  369780\n",
      "X shape =  (1, 539)\n",
      "id client =  369780\n",
      "X shape =  (1, 539)\n",
      "id client =  369780\n",
      "X shape =  (1, 539)\n",
      "id client =  369780\n",
      "X shape =  (1, 539)\n",
      "id client =  369780\n",
      "X shape =  (1, 539)\n",
      "id client =  369780\n",
      "X shape =  (1, 539)\n",
      "id client =  369780\n",
      "X shape =  (1, 539)\n",
      "id client =  369780\n",
      "X shape =  (1, 539)\n",
      "id client =  369780\n",
      "X shape =  (1, 539)\n",
      "id client =  369780\n",
      "X shape =  (1, 539)\n"
     ]
    },
    {
     "ename": "KeyboardInterrupt",
     "evalue": "",
     "output_type": "error",
     "traceback": [
      "\u001b[0;31m---------------------------------------------------------------------------\u001b[0m",
      "\u001b[0;31mKeyboardInterrupt\u001b[0m                         Traceback (most recent call last)",
      "Cell \u001b[0;32mIn[7], line 7\u001b[0m\n\u001b[1;32m      4\u001b[0m subprocess\u001b[38;5;241m.\u001b[39mPopen([\u001b[38;5;124m\"\u001b[39m\u001b[38;5;124mpython\u001b[39m\u001b[38;5;124m\"\u001b[39m, \u001b[38;5;124m\"\u001b[39m\u001b[38;5;124mAPI_01_G10.py\u001b[39m\u001b[38;5;124m\"\u001b[39m])\n\u001b[1;32m      6\u001b[0m \u001b[38;5;66;03m# Ensuite lancer le dashboard\u001b[39;00m\n\u001b[0;32m----> 7\u001b[0m \u001b[43msubprocess\u001b[49m\u001b[38;5;241;43m.\u001b[39;49m\u001b[43mrun\u001b[49m\u001b[43m(\u001b[49m\u001b[43m[\u001b[49m\u001b[38;5;124;43m\"\u001b[39;49m\u001b[38;5;124;43mstreamlit\u001b[39;49m\u001b[38;5;124;43m\"\u001b[39;49m\u001b[43m,\u001b[49m\u001b[43m \u001b[49m\u001b[38;5;124;43m\"\u001b[39;49m\u001b[38;5;124;43mrun\u001b[39;49m\u001b[38;5;124;43m\"\u001b[39;49m\u001b[43m,\u001b[49m\u001b[43m \u001b[49m\u001b[38;5;124;43m\"\u001b[39;49m\u001b[38;5;124;43mDashboard_01_G10.py\u001b[39;49m\u001b[38;5;124;43m\"\u001b[39;49m\u001b[43m]\u001b[49m\u001b[43m)\u001b[49m\n",
      "File \u001b[0;32m~/anaconda3/envs/VERT211/lib/python3.10/subprocess.py:505\u001b[0m, in \u001b[0;36mrun\u001b[0;34m(input, capture_output, timeout, check, *popenargs, **kwargs)\u001b[0m\n\u001b[1;32m    503\u001b[0m \u001b[38;5;28;01mwith\u001b[39;00m Popen(\u001b[38;5;241m*\u001b[39mpopenargs, \u001b[38;5;241m*\u001b[39m\u001b[38;5;241m*\u001b[39mkwargs) \u001b[38;5;28;01mas\u001b[39;00m process:\n\u001b[1;32m    504\u001b[0m     \u001b[38;5;28;01mtry\u001b[39;00m:\n\u001b[0;32m--> 505\u001b[0m         stdout, stderr \u001b[38;5;241m=\u001b[39m \u001b[43mprocess\u001b[49m\u001b[38;5;241;43m.\u001b[39;49m\u001b[43mcommunicate\u001b[49m\u001b[43m(\u001b[49m\u001b[38;5;28;43minput\u001b[39;49m\u001b[43m,\u001b[49m\u001b[43m \u001b[49m\u001b[43mtimeout\u001b[49m\u001b[38;5;241;43m=\u001b[39;49m\u001b[43mtimeout\u001b[49m\u001b[43m)\u001b[49m\n\u001b[1;32m    506\u001b[0m     \u001b[38;5;28;01mexcept\u001b[39;00m TimeoutExpired \u001b[38;5;28;01mas\u001b[39;00m exc:\n\u001b[1;32m    507\u001b[0m         process\u001b[38;5;241m.\u001b[39mkill()\n",
      "File \u001b[0;32m~/anaconda3/envs/VERT211/lib/python3.10/subprocess.py:1146\u001b[0m, in \u001b[0;36mPopen.communicate\u001b[0;34m(self, input, timeout)\u001b[0m\n\u001b[1;32m   1144\u001b[0m         stderr \u001b[38;5;241m=\u001b[39m \u001b[38;5;28mself\u001b[39m\u001b[38;5;241m.\u001b[39mstderr\u001b[38;5;241m.\u001b[39mread()\n\u001b[1;32m   1145\u001b[0m         \u001b[38;5;28mself\u001b[39m\u001b[38;5;241m.\u001b[39mstderr\u001b[38;5;241m.\u001b[39mclose()\n\u001b[0;32m-> 1146\u001b[0m     \u001b[38;5;28;43mself\u001b[39;49m\u001b[38;5;241;43m.\u001b[39;49m\u001b[43mwait\u001b[49m\u001b[43m(\u001b[49m\u001b[43m)\u001b[49m\n\u001b[1;32m   1147\u001b[0m \u001b[38;5;28;01melse\u001b[39;00m:\n\u001b[1;32m   1148\u001b[0m     \u001b[38;5;28;01mif\u001b[39;00m timeout \u001b[38;5;129;01mis\u001b[39;00m \u001b[38;5;129;01mnot\u001b[39;00m \u001b[38;5;28;01mNone\u001b[39;00m:\n",
      "File \u001b[0;32m~/anaconda3/envs/VERT211/lib/python3.10/subprocess.py:1209\u001b[0m, in \u001b[0;36mPopen.wait\u001b[0;34m(self, timeout)\u001b[0m\n\u001b[1;32m   1207\u001b[0m     endtime \u001b[38;5;241m=\u001b[39m _time() \u001b[38;5;241m+\u001b[39m timeout\n\u001b[1;32m   1208\u001b[0m \u001b[38;5;28;01mtry\u001b[39;00m:\n\u001b[0;32m-> 1209\u001b[0m     \u001b[38;5;28;01mreturn\u001b[39;00m \u001b[38;5;28;43mself\u001b[39;49m\u001b[38;5;241;43m.\u001b[39;49m\u001b[43m_wait\u001b[49m\u001b[43m(\u001b[49m\u001b[43mtimeout\u001b[49m\u001b[38;5;241;43m=\u001b[39;49m\u001b[43mtimeout\u001b[49m\u001b[43m)\u001b[49m\n\u001b[1;32m   1210\u001b[0m \u001b[38;5;28;01mexcept\u001b[39;00m \u001b[38;5;167;01mKeyboardInterrupt\u001b[39;00m:\n\u001b[1;32m   1211\u001b[0m     \u001b[38;5;66;03m# https://bugs.python.org/issue25942\u001b[39;00m\n\u001b[1;32m   1212\u001b[0m     \u001b[38;5;66;03m# The first keyboard interrupt waits briefly for the child to\u001b[39;00m\n\u001b[1;32m   1213\u001b[0m     \u001b[38;5;66;03m# exit under the common assumption that it also received the ^C\u001b[39;00m\n\u001b[1;32m   1214\u001b[0m     \u001b[38;5;66;03m# generated SIGINT and will exit rapidly.\u001b[39;00m\n\u001b[1;32m   1215\u001b[0m     \u001b[38;5;28;01mif\u001b[39;00m timeout \u001b[38;5;129;01mis\u001b[39;00m \u001b[38;5;129;01mnot\u001b[39;00m \u001b[38;5;28;01mNone\u001b[39;00m:\n",
      "File \u001b[0;32m~/anaconda3/envs/VERT211/lib/python3.10/subprocess.py:1959\u001b[0m, in \u001b[0;36mPopen._wait\u001b[0;34m(self, timeout)\u001b[0m\n\u001b[1;32m   1957\u001b[0m \u001b[38;5;28;01mif\u001b[39;00m \u001b[38;5;28mself\u001b[39m\u001b[38;5;241m.\u001b[39mreturncode \u001b[38;5;129;01mis\u001b[39;00m \u001b[38;5;129;01mnot\u001b[39;00m \u001b[38;5;28;01mNone\u001b[39;00m:\n\u001b[1;32m   1958\u001b[0m     \u001b[38;5;28;01mbreak\u001b[39;00m  \u001b[38;5;66;03m# Another thread waited.\u001b[39;00m\n\u001b[0;32m-> 1959\u001b[0m (pid, sts) \u001b[38;5;241m=\u001b[39m \u001b[38;5;28;43mself\u001b[39;49m\u001b[38;5;241;43m.\u001b[39;49m\u001b[43m_try_wait\u001b[49m\u001b[43m(\u001b[49m\u001b[38;5;241;43m0\u001b[39;49m\u001b[43m)\u001b[49m\n\u001b[1;32m   1960\u001b[0m \u001b[38;5;66;03m# Check the pid and loop as waitpid has been known to\u001b[39;00m\n\u001b[1;32m   1961\u001b[0m \u001b[38;5;66;03m# return 0 even without WNOHANG in odd situations.\u001b[39;00m\n\u001b[1;32m   1962\u001b[0m \u001b[38;5;66;03m# http://bugs.python.org/issue14396.\u001b[39;00m\n\u001b[1;32m   1963\u001b[0m \u001b[38;5;28;01mif\u001b[39;00m pid \u001b[38;5;241m==\u001b[39m \u001b[38;5;28mself\u001b[39m\u001b[38;5;241m.\u001b[39mpid:\n",
      "File \u001b[0;32m~/anaconda3/envs/VERT211/lib/python3.10/subprocess.py:1917\u001b[0m, in \u001b[0;36mPopen._try_wait\u001b[0;34m(self, wait_flags)\u001b[0m\n\u001b[1;32m   1915\u001b[0m \u001b[38;5;250m\u001b[39m\u001b[38;5;124;03m\"\"\"All callers to this function MUST hold self._waitpid_lock.\"\"\"\u001b[39;00m\n\u001b[1;32m   1916\u001b[0m \u001b[38;5;28;01mtry\u001b[39;00m:\n\u001b[0;32m-> 1917\u001b[0m     (pid, sts) \u001b[38;5;241m=\u001b[39m \u001b[43mos\u001b[49m\u001b[38;5;241;43m.\u001b[39;49m\u001b[43mwaitpid\u001b[49m\u001b[43m(\u001b[49m\u001b[38;5;28;43mself\u001b[39;49m\u001b[38;5;241;43m.\u001b[39;49m\u001b[43mpid\u001b[49m\u001b[43m,\u001b[49m\u001b[43m \u001b[49m\u001b[43mwait_flags\u001b[49m\u001b[43m)\u001b[49m\n\u001b[1;32m   1918\u001b[0m \u001b[38;5;28;01mexcept\u001b[39;00m \u001b[38;5;167;01mChildProcessError\u001b[39;00m:\n\u001b[1;32m   1919\u001b[0m     \u001b[38;5;66;03m# This happens if SIGCLD is set to be ignored or waiting\u001b[39;00m\n\u001b[1;32m   1920\u001b[0m     \u001b[38;5;66;03m# for child processes has otherwise been disabled for our\u001b[39;00m\n\u001b[1;32m   1921\u001b[0m     \u001b[38;5;66;03m# process.  This child is dead, we can't get the status.\u001b[39;00m\n\u001b[1;32m   1922\u001b[0m     pid \u001b[38;5;241m=\u001b[39m \u001b[38;5;28mself\u001b[39m\u001b[38;5;241m.\u001b[39mpid\n",
      "\u001b[0;31mKeyboardInterrupt\u001b[0m: "
     ]
    }
   ],
   "source": [
    "import subprocess\n",
    "\n",
    "# Lancer l'API\n",
    "subprocess.Popen([\"python\", \"API_01_G10.py\"])\n",
    "\n",
    "# Ensuite lancer le dashboard\n",
    "subprocess.run([\"streamlit\", \"run\", \"Dashboard_01_G10.py\"])"
   ]
  }
 ],
 "metadata": {
  "kernelspec": {
   "display_name": "Python 3 (ipykernel)",
   "language": "python",
   "name": "python3"
  },
  "language_info": {
   "codemirror_mode": {
    "name": "ipython",
    "version": 3
   },
   "file_extension": ".py",
   "mimetype": "text/x-python",
   "name": "python",
   "nbconvert_exporter": "python",
   "pygments_lexer": "ipython3",
   "version": "3.10.16"
  }
 },
 "nbformat": 4,
 "nbformat_minor": 5
}
